
LENOVO@NITHYASHREE MINGW64 /d/CodesAndProjects/WorkSpace
$ dir
Profile_Rest_Api

LENOVO@NITHYASHREE MINGW64 /d/CodesAndProjects/WorkSpace
$ ^C

LENOVO@NITHYASHREE MINGW64 /d/CodesAndProjects/WorkSpace
$ cd Profile_Rest_Api

LENOVO@NITHYASHREE MINGW64 /d/CodesAndProjects/WorkSpace/Profile_Rest_Api (main)
$ git add .

LENOVO@NITHYASHREE MINGW64 /d/CodesAndProjects/WorkSpace/Profile_Rest_Api (main)
$ git commit -m "3rd commit"
[main 0b6197a] 3rd commit
 1 file changed, 326 insertions(+)
 create mode 100644 dayone.txt

LENOVO@NITHYASHREE MINGW64 /d/CodesAndProjects/WorkSpace/Profile_Rest_Api (main)
$ git push
To https://github.com/sanjayadhi/Pofile_REST_API.git
 ! [rejected]        main -> main (fetch first)
error: failed to push some refs to 'https://github.com/sanjayadhi/Pofile_REST_API.git'
hint: Updates were rejected because the remote contains work that you do
hint: not have locally. This is usually caused by another repository pushing
hint: to the same ref. You may want to first integrate the remote changes
hint: (e.g., 'git pull ...') before pushing again.
hint: See the 'Note about fast-forwards' in 'git push --help' for details.

LENOVO@NITHYASHREE MINGW64 /d/CodesAndProjects/WorkSpace/Profile_Rest_Api (main)
$ git push .
Everything up-to-date

LENOVO@NITHYASHREE MINGW64 /d/CodesAndProjects/WorkSpace/Profile_Rest_Api (main)
$ vagrant ssh
VM must be running to open SSH connection. Run `vagrant up`
to start the virtual machine.

LENOVO@NITHYASHREE MINGW64 /d/CodesAndProjects/WorkSpace/Profile_Rest_Api (main)
$ vagrant up
Bringing machine 'default' up with 'virtualbox' provider...
==> default: Checking if box 'ubuntu/bionic64' version '20200304.0.0' is up to date...
==> default: Clearing any previously set forwarded ports...
==> default: Clearing any previously set network interfaces...
==> default: Preparing network interfaces based on configuration...
    default: Adapter 1: nat
==> default: Forwarding ports...
    default: 8000 (guest) => 8000 (host) (adapter 1)
    default: 22 (guest) => 2222 (host) (adapter 1)
==> default: Running 'pre-boot' VM customizations...
==> default: Booting VM...
==> default: Waiting for machine to boot. This may take a few minutes...
    default: SSH address: 127.0.0.1:2222
    default: SSH username: vagrant
    default: SSH auth method: private key
    default: Warning: Connection reset. Retrying...
    default: Warning: Connection aborted. Retrying...
==> default: Machine booted and ready!
==> default: Checking for guest additions in VM...
    default: The guest additions on this VM do not match the installed version of
    default: VirtualBox! In most cases this is fine, but in rare cases it can
    default: prevent things such as shared folders from working properly. If you see
    default: shared folder errors, please make sure the guest additions within the
    default: virtual machine match the version of VirtualBox you have installed on
    default: your host and reload your VM.
    default:
    default: Guest Additions Version: 5.2.42
    default: VirtualBox Version: 6.1
==> default: Mounting shared folders...
    default: /vagrant => D:/CodesAndProjects/WorkSpace/Profile_Rest_Api
==> default: Machine already provisioned. Run `vagrant provision` or use the `--provision`
==> default: flag to force provisioning. Provisioners marked to run always will still run.

LENOVO@NITHYASHREE MINGW64 /d/CodesAndProjects/WorkSpace/Profile_Rest_Api (main)
$ dir
License  Vagrantfile  dayone.txt  helloworld.py  readme.md  ubuntu-bionic-18.04-cloudimg-console.log

LENOVO@NITHYASHREE MINGW64 /d/CodesAndProjects/WorkSpace/Profile_Rest_Api (main)
$ cd vagrant
bash: cd: vagrant: No such file or directory

LENOVO@NITHYASHREE MINGW64 /d/CodesAndProjects/WorkSpace/Profile_Rest_Api (main)
$ vagrant ssh
Welcome to Ubuntu 18.04.5 LTS (GNU/Linux 4.15.0-141-generic x86_64)

 * Documentation:  https://help.ubuntu.com
 * Management:     https://landscape.canonical.com
 * Support:        https://ubuntu.com/advantage

  System information as of Wed Apr 14 05:17:31 UTC 2021

  System load:  0.0               Processes:             96
  Usage of /:   3.1% of 38.71GB   Users logged in:       0
  Memory usage: 12%               IP address for enp0s3: 10.0.2.15
  Swap usage:   0%


4 packages can be updated.
2 of these updates are security updates.
To see these additional updates run: apt list --upgradable

New release '20.04.2 LTS' available.
Run 'do-release-upgrade' to upgrade to it.


Last login: Tue Apr 13 17:22:49 2021 from 10.0.2.2
vagrant@ubuntu-bionic:~$ cd vagrant
-bash: cd: vagrant: No such file or directory
vagrant@ubuntu-bionic:~$ cd /vagrant/
vagrant@ubuntu-bionic:/vagrant$ python -m venv ~/env
vagrant@ubuntu-bionic:/vagrant$ source ~/env/bin/activate
(env) vagrant@ubuntu-bionic:/vagrant$ decativate
decativate: command not found
(env) vagrant@ubuntu-bionic:/vagrant$ deactivate
vagrant@ubuntu-bionic:/vagrant$ source ~/env/bin/activate
(env) vagrant@ubuntu-bionic:/vagrant$ pip install -r requirements.txt
Collecting Django==2.2 (from -r requirements.txt (line 1))
  Downloading https://files.pythonhosted.org/packages/54/85/0bef63668fb170888c1a2970ec897d4528d6072f32dee27653381a332642/Django-2.2-py3-none-any.whl (7.4MB)
    100% |████████████████████████████████| 7.5MB 126kB/s
Collecting Djangrestframework==3.9.2 (from -r requirements.txt (line 2))
Exception:
Traceback (most recent call last):
  File "/home/vagrant/env/lib/python3.6/site-packages/pip/basecommand.py", line 215, in main
    status = self.run(options, args)
  File "/home/vagrant/env/lib/python3.6/site-packages/pip/commands/install.py", line 353, in run
    wb.build(autobuilding=True)
  File "/home/vagrant/env/lib/python3.6/site-packages/pip/wheel.py", line 749, in build
    self.requirement_set.prepare_files(self.finder)
  File "/home/vagrant/env/lib/python3.6/site-packages/pip/req/req_set.py", line 380, in prepare_files
    ignore_dependencies=self.ignore_dependencies))
  File "/home/vagrant/env/lib/python3.6/site-packages/pip/req/req_set.py", line 554, in _prepare_file
    require_hashes
  File "/home/vagrant/env/lib/python3.6/site-packages/pip/req/req_install.py", line 278, in populate_link
    self.link = finder.find_requirement(self, upgrade)
  File "/home/vagrant/env/lib/python3.6/site-packages/pip/index.py", line 465, in find_requirement
    all_candidates = self.find_all_candidates(req.name)
  File "/home/vagrant/env/lib/python3.6/site-packages/pip/index.py", line 423, in find_all_candidates
    for page in self._get_pages(url_locations, project_name):
  File "/home/vagrant/env/lib/python3.6/site-packages/pip/index.py", line 568, in _get_pages
    page = self._get_page(location)
  File "/home/vagrant/env/lib/python3.6/site-packages/pip/index.py", line 683, in _get_page
    return HTMLPage.get_page(link, session=self.session)
  File "/home/vagrant/env/lib/python3.6/site-packages/pip/index.py", line 795, in get_page
    resp.raise_for_status()
  File "/home/vagrant/env/share/python-wheels/requests-2.18.4-py2.py3-none-any.whl/requests/models.py", line 935, in raise_for_status
    raise HTTPError(http_error_msg, response=self)
requests.exceptions.HTTPError: 404 Client Error: Not Found for url: https://pypi.org/simple/djangrestframework/
(env) vagrant@ubuntu-bionic:/vagrant$
(env) vagrant@ubuntu-bionic:/vagrant$
(env) vagrant@ubuntu-bionic:/vagrant$
(env) vagrant@ubuntu-bionic:/vagrant$
(env) vagrant@ubuntu-bionic:/vagrant$
(env) vagrant@ubuntu-bionic:/vagrant$ pip install -r requirements.txt
Collecting Django==2.2 (from -r requirements.txt (line 1))
  Using cached https://files.pythonhosted.org/packages/54/85/0bef63668fb170888c1a2970ec897d4528d6072f32dee27653381a332642/Django-2.2-py3-none-any.whl
Collecting Djangrestframework==3.12.4 (from -r requirements.txt (line 2))
Exception:
Traceback (most recent call last):
  File "/home/vagrant/env/lib/python3.6/site-packages/pip/basecommand.py", line 215, in main
    status = self.run(options, args)
  File "/home/vagrant/env/lib/python3.6/site-packages/pip/commands/install.py", line 353, in run
    wb.build(autobuilding=True)
  File "/home/vagrant/env/lib/python3.6/site-packages/pip/wheel.py", line 749, in build
    self.requirement_set.prepare_files(self.finder)
  File "/home/vagrant/env/lib/python3.6/site-packages/pip/req/req_set.py", line 380, in prepare_files
    ignore_dependencies=self.ignore_dependencies))
  File "/home/vagrant/env/lib/python3.6/site-packages/pip/req/req_set.py", line 554, in _prepare_file
    require_hashes
  File "/home/vagrant/env/lib/python3.6/site-packages/pip/req/req_install.py", line 278, in populate_link
    self.link = finder.find_requirement(self, upgrade)
  File "/home/vagrant/env/lib/python3.6/site-packages/pip/index.py", line 465, in find_requirement
    all_candidates = self.find_all_candidates(req.name)
  File "/home/vagrant/env/lib/python3.6/site-packages/pip/index.py", line 423, in find_all_candidates
    for page in self._get_pages(url_locations, project_name):
  File "/home/vagrant/env/lib/python3.6/site-packages/pip/index.py", line 568, in _get_pages
    page = self._get_page(location)
  File "/home/vagrant/env/lib/python3.6/site-packages/pip/index.py", line 683, in _get_page
    return HTMLPage.get_page(link, session=self.session)
  File "/home/vagrant/env/lib/python3.6/site-packages/pip/index.py", line 795, in get_page
    resp.raise_for_status()
  File "/home/vagrant/env/share/python-wheels/requests-2.18.4-py2.py3-none-any.whl/requests/models.py", line 935, in raise_for_status
    raise HTTPError(http_error_msg, response=self)
requests.exceptions.HTTPError: 404 Client Error: Not Found for url: https://pypi.org/simple/djangrestframework/
(env) vagrant@ubuntu-bionic:/vagrant$
(env) vagrant@ubuntu-bionic:/vagrant$
(env) vagrant@ubuntu-bionic:/vagrant$
(env) vagrant@ubuntu-bionic:/vagrant$
(env) vagrant@ubuntu-bionic:/vagrant$
(env) vagrant@ubuntu-bionic:/vagrant$ pip install -r requirements.txt
Collecting Django==2.2 (from -r requirements.txt (line 1))
  Using cached https://files.pythonhosted.org/packages/54/85/0bef63668fb170888c1a2970ec897d4528d6072f32dee27653381a332642/Django-2.2-py3-none-any.whl
Collecting Djangorestframework==3.9.4 (from -r requirements.txt (line 2))
  Downloading https://files.pythonhosted.org/packages/1b/fe/fcebec2a98fbd1548da1c12ce8d7f634a02a9cce350833fa227a625ec624/djangorestframework-3.9.4-py2.py3-none-any.whl (911kB)
    100% |████████████████████████████████| 921kB 666kB/s
Collecting sqlparse (from Django==2.2->-r requirements.txt (line 1))
  Downloading https://files.pythonhosted.org/packages/14/05/6e8eb62ca685b10e34051a80d7ea94b7137369d8c0be5c3b9d9b6e3f5dae/sqlparse-0.4.1-py3-none-any.whl (42kB)
    100% |████████████████████████████████| 51kB 2.4MB/s
Collecting pytz (from Django==2.2->-r requirements.txt (line 1))
  Downloading https://files.pythonhosted.org/packages/70/94/784178ca5dd892a98f113cdd923372024dc04b8d40abe77ca76b5fb90ca6/pytz-2021.1-py2.py3-none-any.whl (510kB)
    100% |████████████████████████████████| 512kB 1.0MB/s
Installing collected packages: sqlparse, pytz, Django, Djangorestframework
Successfully installed Django-2.2 Djangorestframework-3.9.4 pytz-2021.1 sqlparse-0.4.1
(env) vagrant@ubuntu-bionic:/vagrant$
(env) vagrant@ubuntu-bionic:/vagrant$
(env) vagrant@ubuntu-bionic:/vagrant$
(env) vagrant@ubuntu-bionic:/vagrant$
(env) vagrant@ubuntu-bionic:/vagrant$
(env) vagrant@ubuntu-bionic:/vagrant$
(env) vagrant@ubuntu-bionic:/vagrant$
(env) vagrant@ubuntu-bionic:/vagrant$
(env) vagrant@ubuntu-bionic:/vagrant$
(env) vagrant@ubuntu-bionic:/vagrant$
(env) vagrant@ubuntu-bionic:/vagrant$
(env) vagrant@ubuntu-bionic:/vagrant$
(env) vagrant@ubuntu-bionic:/vagrant$
(env) vagrant@ubuntu-bionic:/vagrant$
(env) vagrant@ubuntu-bionic:/vagrant$
(env) vagrant@ubuntu-bionic:/vagrant$
(env) vagrant@ubuntu-bionic:/vagrant$
(env) vagrant@ubuntu-bionic:/vagrant$
(env) vagrant@ubuntu-bionic:/vagrant$
(env) vagrant@ubuntu-bionic:/vagrant$
(env) vagrant@ubuntu-bionic:/vagrant$
(env) vagrant@ubuntu-bionic:/vagrant$
(env) vagrant@ubuntu-bionic:/vagrant$
(env) vagrant@ubuntu-bionic:/vagrant$
(env) vagrant@ubuntu-bionic:/vagrant$
(env) vagrant@ubuntu-bionic:/vagrant$
(env) vagrant@ubuntu-bionic:/vagrant$
(env) vagrant@ubuntu-bionic:/vagrant$
(env) vagrant@ubuntu-bionic:/vagrant$
(env) vagrant@ubuntu-bionic:/vagrant$
(env) vagrant@ubuntu-bionic:/vagrant$
(env) vagrant@ubuntu-bionic:/vagrant$
(env) vagrant@ubuntu-bionic:/vagrant$
(env) vagrant@ubuntu-bionic:/vagrant$
(env) vagrant@ubuntu-bionic:/vagrant$
(env) vagrant@ubuntu-bionic:/vagrant$
(env) vagrant@ubuntu-bionic:/vagrant$
(env) vagrant@ubuntu-bionic:/vagrant$
(env) vagrant@ubuntu-bionic:/vagrant$
(env) vagrant@ubuntu-bionic:/vagrant$
(env) vagrant@ubuntu-bionic:/vagrant$
(env) vagrant@ubuntu-bionic:/vagrant$
(env) vagrant@ubuntu-bionic:/vagrant$
(env) vagrant@ubuntu-bionic:/vagrant$
(env) vagrant@ubuntu-bionic:/vagrant$
(env) vagrant@ubuntu-bionic:/vagrant$
(env) vagrant@ubuntu-bionic:/vagrant$
(env) vagrant@ubuntu-bionic:/vagrant$ django-admin.py stratproject profiles_project .
No Django settings specified.
Unknown command: 'stratproject'. Did you mean startproject?
Type 'django-admin.py help' for usage.
(env) vagrant@ubuntu-bionic:/vagrant$ django-admin stratproject profiles_project .
No Django settings specified.
Unknown command: 'stratproject'. Did you mean startproject?
Type 'django-admin help' for usage.
(env) vagrant@ubuntu-bionic:/vagrant$ django-admin.py startproject profiles_project .
(env) vagrant@ubuntu-bionic:/vagrant$ dir
License           Vagrantfile    manage.py         ubuntu-bionic-18.04-cloudimg-console.log
Requirement.txt   dayone.txt     profiles_project
Requirements.txt  helloworld.py  readme.md
(env) vagrant@ubuntu-bionic:/vagrant$ ^C
(env) vagrant@ubuntu-bionic:/vagrant$ ^C
(env) vagrant@ubuntu-bionic:/vagrant$ python manage.py startapp profiles_api
(env) vagrant@ubuntu-bionic:/vagrant$ ^C
(env) vagrant@ubuntu-bionic:/vagrant$ python manage.py runserver  0.0.0.0:8000
Watching for file changes with StatReloader
Performing system checks...

System check identified no issues (0 silenced).

You have 19 unapplied migration(s). Your project may not work properly until you apply the migrations for app(s): admin, auth, authtoken, contenttypes, sessions.
Run 'python manage.py migrate' to apply them.

April 14, 2021 - 06:08:04
Django version 2.2, using settings 'profiles_project.settings'
Starting development server at http://0.0.0.0:8000/
Quit the server with CONTROL-C.
[14/Apr/2021 06:09:16] "GET / HTTP/1.1" 200 16348
[14/Apr/2021 06:09:17] "GET /static/admin/css/fonts.css HTTP/1.1" 200 423
[14/Apr/2021 06:09:17] "GET /static/admin/fonts/Roboto-Regular-webfont.woff HTTP/1.1" 200 85876
[14/Apr/2021 06:09:17] "GET /static/admin/fonts/Roboto-Bold-webfont.woff HTTP/1.1" 200 86184
[14/Apr/2021 06:09:17] "GET /static/admin/fonts/Roboto-Light-webfont.woff HTTP/1.1" 200 85692
Not Found: /favicon.ico
[14/Apr/2021 06:09:17] "GET /favicon.ico HTTP/1.1" 404 1982
[14/Apr/2021 06:09:41] "GET / HTTP/1.1" 200 16348
[14/Apr/2021 06:09:45] "GET / HTTP/1.1" 200 16348
[14/Apr/2021 06:09:46] "GET / HTTP/1.1" 200 16348
[14/Apr/2021 06:09:47] "GET / HTTP/1.1" 200 16348
^C(env) vagrant@ubuntu-bionic:/vagrant$ python manage.py runserver  0.0.0.0:8000
Watching for file changes with StatReloader
Performing system checks...

System check identified no issues (0 silenced).

You have 19 unapplied migration(s). Your project may not work properly until you apply the migrations for app(s): admin, auth, authtoken, contenttypes, sessions.
Run 'python manage.py migrate' to apply them.

April 14, 2021 - 06:10:01
Django version 2.2, using settings 'profiles_project.settings'
Starting development server at http://0.0.0.0:8000/
Quit the server with CONTROL-C.
[14/Apr/2021 06:10:01] "GET / HTTP/1.1" 200 16348
[14/Apr/2021 06:10:03] "GET / HTTP/1.1" 200 16348
[14/Apr/2021 06:10:04] "GET / HTTP/1.1" 200 16348
[14/Apr/2021 06:10:04] "GET / HTTP/1.1" 200 16348
/vagrant/profiles_api/models.py changed, reloading.
Watching for file changes with StatReloader
Exception in thread Thread-1:
Traceback (most recent call last):
  File "/usr/lib/python3.6/threading.py", line 916, in _bootstrap_inner
    self.run()
  File "/usr/lib/python3.6/threading.py", line 864, in run
    self._target(*self._args, **self._kwargs)
  File "/home/vagrant/env/lib/python3.6/site-packages/django/utils/autoreload.py", line 54, in wrapper
    fn(*args, **kwargs)
  File "/home/vagrant/env/lib/python3.6/site-packages/django/core/management/commands/runserver.py", line 109, in inner_run
    autoreload.raise_last_exception()
  File "/home/vagrant/env/lib/python3.6/site-packages/django/utils/autoreload.py", line 77, in raise_last_exception
    raise _exception[0](_exception[1]).with_traceback(_exception[2])
  File "/home/vagrant/env/lib/python3.6/site-packages/django/utils/autoreload.py", line 54, in wrapper
    fn(*args, **kwargs)
  File "/home/vagrant/env/lib/python3.6/site-packages/django/__init__.py", line 24, in setup
    apps.populate(settings.INSTALLED_APPS)
  File "/home/vagrant/env/lib/python3.6/site-packages/django/apps/registry.py", line 114, in populate
    app_config.import_models()
  File "/home/vagrant/env/lib/python3.6/site-packages/django/apps/config.py", line 211, in import_models
    self.models_module = import_module(models_module_name)
  File "/usr/lib/python3.6/importlib/__init__.py", line 126, in import_module
    return _bootstrap._gcd_import(name[level:], package, level)
  File "<frozen importlib._bootstrap>", line 994, in _gcd_import
  File "<frozen importlib._bootstrap>", line 971, in _find_and_load
  File "<frozen importlib._bootstrap>", line 955, in _find_and_load_unlocked
  File "<frozen importlib._bootstrap>", line 665, in _load_unlocked
  File "<frozen importlib._bootstrap_external>", line 678, in exec_module
  File "<frozen importlib._bootstrap>", line 219, in _call_with_frames_removed
  File "/vagrant/profiles_api/models.py", line 4, in <module>
    from django.contib.auth.models import AbstractBaseUser
ModuleNotFoundError: No module named 'django.contib'

Traceback (most recent call last):
  File "/home/vagrant/env/lib/python3.6/site-packages/django/apps/registry.py", line 155, in get_app_config
    return self.app_configs[app_label]
KeyError: 'admin'

During handling of the above exception, another exception occurred:

Traceback (most recent call last):
  File "manage.py", line 21, in <module>
    main()
  File "manage.py", line 17, in main
    execute_from_command_line(sys.argv)
  File "/home/vagrant/env/lib/python3.6/site-packages/django/core/management/__init__.py", line 381, in execute_from_command_line
    utility.execute()
  File "/home/vagrant/env/lib/python3.6/site-packages/django/core/management/__init__.py", line 375, in execute
    self.fetch_command(subcommand).run_from_argv(self.argv)
  File "/home/vagrant/env/lib/python3.6/site-packages/django/core/management/base.py", line 323, in run_from_argv
    self.execute(*args, **cmd_options)
  File "/home/vagrant/env/lib/python3.6/site-packages/django/core/management/commands/runserver.py", line 60, in execute
    super().execute(*args, **options)
  File "/home/vagrant/env/lib/python3.6/site-packages/django/core/management/base.py", line 364, in execute
    output = self.handle(*args, **options)
  File "/home/vagrant/env/lib/python3.6/site-packages/django/core/management/commands/runserver.py", line 95, in handle
    self.run(**options)
  File "/home/vagrant/env/lib/python3.6/site-packages/django/core/management/commands/runserver.py", line 102, in run
    autoreload.run_with_reloader(self.inner_run, **options)
  File "/home/vagrant/env/lib/python3.6/site-packages/django/utils/autoreload.py", line 579, in run_with_reloader
    start_django(reloader, main_func, *args, **kwargs)
  File "/home/vagrant/env/lib/python3.6/site-packages/django/utils/autoreload.py", line 564, in start_django
    reloader.run(django_main_thread)
  File "/home/vagrant/env/lib/python3.6/site-packages/django/utils/autoreload.py", line 272, in run
    get_resolver().urlconf_module
  File "/home/vagrant/env/lib/python3.6/site-packages/django/utils/functional.py", line 80, in __get__
    res = instance.__dict__[self.name] = self.func(instance)
  File "/home/vagrant/env/lib/python3.6/site-packages/django/urls/resolvers.py", line 564, in urlconf_module
    return import_module(self.urlconf_name)
  File "/usr/lib/python3.6/importlib/__init__.py", line 126, in import_module
    return _bootstrap._gcd_import(name[level:], package, level)
  File "<frozen importlib._bootstrap>", line 994, in _gcd_import
  File "<frozen importlib._bootstrap>", line 971, in _find_and_load
  File "<frozen importlib._bootstrap>", line 955, in _find_and_load_unlocked
  File "<frozen importlib._bootstrap>", line 665, in _load_unlocked
  File "<frozen importlib._bootstrap_external>", line 678, in exec_module
  File "<frozen importlib._bootstrap>", line 219, in _call_with_frames_removed
  File "/vagrant/profiles_project/urls.py", line 20, in <module>
    path('admin/', admin.site.urls),
  File "/home/vagrant/env/lib/python3.6/site-packages/django/utils/functional.py", line 256, in inner
    self._setup()
  File "/home/vagrant/env/lib/python3.6/site-packages/django/contrib/admin/sites.py", line 529, in _setup
    AdminSiteClass = import_string(apps.get_app_config('admin').default_site)
  File "/home/vagrant/env/lib/python3.6/site-packages/django/apps/registry.py", line 162, in get_app_config
    raise LookupError(message)
LookupError: No installed app with label 'admin'.
(env) vagrant@ubuntu-bionic:/vagrant$ ppython manage.py makemigrations profiles_api

Command 'ppython' not found, did you mean:

  command 'python' from deb python3
  command 'python' from deb python
  command 'python' from deb python-minimal
  command 'ipython' from deb ipython
  command 'bpython' from deb bpython
  command 'pmpython' from deb pcp
  command 'pvpython' from deb paraview-python

Try: apt install <deb name>

(env) vagrant@ubuntu-bionic:/vagrant$ python manage.py makemigrations profiles_api
Traceback (most recent call last):
  File "manage.py", line 21, in <module>
    main()
  File "manage.py", line 17, in main
    execute_from_command_line(sys.argv)
  File "/home/vagrant/env/lib/python3.6/site-packages/django/core/management/__init__.py", line 381, in execute_from_command_line
    utility.execute()
  File "/home/vagrant/env/lib/python3.6/site-packages/django/core/management/__init__.py", line 357, in execute
    django.setup()
  File "/home/vagrant/env/lib/python3.6/site-packages/django/__init__.py", line 24, in setup
    apps.populate(settings.INSTALLED_APPS)
  File "/home/vagrant/env/lib/python3.6/site-packages/django/apps/registry.py", line 114, in populate
    app_config.import_models()
  File "/home/vagrant/env/lib/python3.6/site-packages/django/apps/config.py", line 211, in import_models
    self.models_module = import_module(models_module_name)
  File "/usr/lib/python3.6/importlib/__init__.py", line 126, in import_module
    return _bootstrap._gcd_import(name[level:], package, level)
  File "<frozen importlib._bootstrap>", line 994, in _gcd_import
  File "<frozen importlib._bootstrap>", line 971, in _find_and_load
  File "<frozen importlib._bootstrap>", line 955, in _find_and_load_unlocked
  File "<frozen importlib._bootstrap>", line 665, in _load_unlocked
  File "<frozen importlib._bootstrap_external>", line 674, in exec_module
  File "<frozen importlib._bootstrap_external>", line 781, in get_code
  File "<frozen importlib._bootstrap_external>", line 741, in source_to_code
  File "<frozen importlib._bootstrap>", line 219, in _call_with_frames_removed
  File "/vagrant/profiles_api/models.py", line 54
    """ return string representation of our user?"""
                                                   ^
IndentationError: expected an indented block
(env) vagrant@ubuntu-bionic:/vagrant$ python manage.py makemigrations profiles_api
Traceback (most recent call last):
  File "manage.py", line 21, in <module>
    main()
  File "manage.py", line 17, in main
    execute_from_command_line(sys.argv)
  File "/home/vagrant/env/lib/python3.6/site-packages/django/core/management/__init__.py", line 381, in execute_from_command_line
    utility.execute()
  File "/home/vagrant/env/lib/python3.6/site-packages/django/core/management/__init__.py", line 357, in execute
    django.setup()
  File "/home/vagrant/env/lib/python3.6/site-packages/django/__init__.py", line 24, in setup
    apps.populate(settings.INSTALLED_APPS)
  File "/home/vagrant/env/lib/python3.6/site-packages/django/apps/registry.py", line 114, in populate
    app_config.import_models()
  File "/home/vagrant/env/lib/python3.6/site-packages/django/apps/config.py", line 211, in import_models
    self.models_module = import_module(models_module_name)
  File "/usr/lib/python3.6/importlib/__init__.py", line 126, in import_module
    return _bootstrap._gcd_import(name[level:], package, level)
  File "<frozen importlib._bootstrap>", line 994, in _gcd_import
  File "<frozen importlib._bootstrap>", line 971, in _find_and_load
  File "<frozen importlib._bootstrap>", line 955, in _find_and_load_unlocked
  File "<frozen importlib._bootstrap>", line 665, in _load_unlocked
  File "<frozen importlib._bootstrap_external>", line 678, in exec_module
  File "<frozen importlib._bootstrap>", line 219, in _call_with_frames_removed
  File "/vagrant/profiles_api/models.py", line 3, in <module>
    from django.contib.auth.models import AbstractBaseUser
ModuleNotFoundError: No module named 'django.contib'
(env) vagrant@ubuntu-bionic:/vagrant$ python manage.py makemigrations profiles_api
Traceback (most recent call last):
  File "manage.py", line 21, in <module>
    main()
  File "manage.py", line 17, in main
    execute_from_command_line(sys.argv)
  File "/home/vagrant/env/lib/python3.6/site-packages/django/core/management/__init__.py", line 381, in execute_from_command_line
    utility.execute()
  File "/home/vagrant/env/lib/python3.6/site-packages/django/core/management/__init__.py", line 357, in execute
    django.setup()
  File "/home/vagrant/env/lib/python3.6/site-packages/django/__init__.py", line 24, in setup
    apps.populate(settings.INSTALLED_APPS)
  File "/home/vagrant/env/lib/python3.6/site-packages/django/apps/registry.py", line 114, in populate
    app_config.import_models()
  File "/home/vagrant/env/lib/python3.6/site-packages/django/apps/config.py", line 211, in import_models
    self.models_module = import_module(models_module_name)
  File "/usr/lib/python3.6/importlib/__init__.py", line 126, in import_module
    return _bootstrap._gcd_import(name[level:], package, level)
  File "<frozen importlib._bootstrap>", line 994, in _gcd_import
  File "<frozen importlib._bootstrap>", line 971, in _find_and_load
  File "<frozen importlib._bootstrap>", line 955, in _find_and_load_unlocked
  File "<frozen importlib._bootstrap>", line 665, in _load_unlocked
  File "<frozen importlib._bootstrap_external>", line 678, in exec_module
  File "<frozen importlib._bootstrap>", line 219, in _call_with_frames_removed
  File "/vagrant/profiles_api/models.py", line 33, in <module>
    class UserProfile(AbstractBaseUser,PermissionsMixin): #inheritance
  File "/vagrant/profiles_api/models.py", line 40, in UserProfile
    objects = UserProfileManager() #classto manage the models above
NameError: name 'UserProfileManager' is not defined
(env) vagrant@ubuntu-bionic:/vagrant$ python manage.py makemigrations profiles_api
Migrations for 'profiles_api':
  profiles_api/migrations/0001_initial.py
    - Create model UserProfile
(env) vagrant@ubuntu-bionic:/vagrant$ python manage.py migrate
Operations to perform:
  Apply all migrations: admin, auth, authtoken, contenttypes, profiles_api, sessions
Running migrations:
  Applying contenttypes.0001_initial... OK
  Applying contenttypes.0002_remove_content_type_name... OK
  Applying auth.0001_initial... OK
  Applying auth.0002_alter_permission_name_max_length... OK
  Applying auth.0003_alter_user_email_max_length... OK
  Applying auth.0004_alter_user_username_opts... OK
  Applying auth.0005_alter_user_last_login_null... OK
  Applying auth.0006_require_contenttypes_0002... OK
  Applying auth.0007_alter_validators_add_error_messages... OK
  Applying auth.0008_alter_user_username_max_length... OK
  Applying auth.0009_alter_user_last_name_max_length... OK
  Applying auth.0010_alter_group_name_max_length... OK
  Applying auth.0011_update_proxy_permissions... OK
  Applying profiles_api.0001_initial... OK
  Applying admin.0001_initial... OK
  Applying admin.0002_logentry_remove_auto_add... OK
  Applying admin.0003_logentry_add_action_flag_choices... OK
  Applying authtoken.0001_initial... OK
  Applying authtoken.0002_auto_20160226_1747... OK
  Applying sessions.0001_initial... OK
(env) vagrant@ubuntu-bionic:/vagrant$ python manage.py createsuperuser
Email: sanjaynithi0@gmail.com
Password:
Password (again):
Error: Your passwords didn't match.
Password:
Password (again):
Error: Your passwords didn't match.
Password:
Password (again):
This password is too short. It must contain at least 8 characters.
This password is too common.
This password is entirely numeric.
Bypass password validation and create user anyway? [y/N]: y
Traceback (most recent call last):
  File "manage.py", line 21, in <module>
    main()
  File "manage.py", line 17, in main
    execute_from_command_line(sys.argv)
  File "/home/vagrant/env/lib/python3.6/site-packages/django/core/management/__init__.py", line 381, in execute_from_command_line
    utility.execute()
  File "/home/vagrant/env/lib/python3.6/site-packages/django/core/management/__init__.py", line 375, in execute
    self.fetch_command(subcommand).run_from_argv(self.argv)
  File "/home/vagrant/env/lib/python3.6/site-packages/django/core/management/base.py", line 323, in run_from_argv
    self.execute(*args, **cmd_options)
  File "/home/vagrant/env/lib/python3.6/site-packages/django/contrib/auth/management/commands/createsuperuser.py", line 61, in execute
    return super().execute(*args, **options)
  File "/home/vagrant/env/lib/python3.6/site-packages/django/core/management/base.py", line 364, in execute
    output = self.handle(*args, **options)
  File "/home/vagrant/env/lib/python3.6/site-packages/django/contrib/auth/management/commands/createsuperuser.py", line 156, in handle
    self.UserModel._default_manager.db_manager(database).create_superuser(**user_data)
AttributeError: 'userProfileManager' object has no attribute 'create_superuser'
(env) vagrant@ubuntu-bionic:/vagrant$ python manage.py createsuperuser
Email: sanjaynithi0@gmail.com
Password:
Password (again):
This password is too short. It must contain at least 8 characters.
This password is too common.
This password is entirely numeric.
Bypass password validation and create user anyway? [y/N]: y
Traceback (most recent call last):
  File "manage.py", line 21, in <module>
    main()
  File "manage.py", line 17, in main
    execute_from_command_line(sys.argv)
  File "/home/vagrant/env/lib/python3.6/site-packages/django/core/management/__init__.py", line 381, in execute_from_command_line
    utility.execute()
  File "/home/vagrant/env/lib/python3.6/site-packages/django/core/management/__init__.py", line 375, in execute
    self.fetch_command(subcommand).run_from_argv(self.argv)
  File "/home/vagrant/env/lib/python3.6/site-packages/django/core/management/base.py", line 323, in run_from_argv
    self.execute(*args, **cmd_options)
  File "/home/vagrant/env/lib/python3.6/site-packages/django/contrib/auth/management/commands/createsuperuser.py", line 61, in execute
    return super().execute(*args, **options)
  File "/home/vagrant/env/lib/python3.6/site-packages/django/core/management/base.py", line 364, in execute
    output = self.handle(*args, **options)
  File "/home/vagrant/env/lib/python3.6/site-packages/django/contrib/auth/management/commands/createsuperuser.py", line 156, in handle
    self.UserModel._default_manager.db_manager(database).create_superuser(**user_data)
TypeError: create_superuser() missing 1 required positional argument: 'name'
(env) vagrant@ubuntu-bionic:/vagrant$ ^C
(env) vagrant@ubuntu-bionic:/vagrant$ ^C
(env) vagrant@ubuntu-bionic:/vagrant$ python manage.py createsuperuser
Email: sanjaynithi0@gmail.com
Password:
Password (again):
This password is too short. It must contain at least 8 characters.
Bypass password validation and create user anyway? [y/N]: y
Traceback (most recent call last):
  File "manage.py", line 21, in <module>
    main()
  File "manage.py", line 17, in main
    execute_from_command_line(sys.argv)
  File "/home/vagrant/env/lib/python3.6/site-packages/django/core/management/__init__.py", line 381, in execute_from_command_line
    utility.execute()
  File "/home/vagrant/env/lib/python3.6/site-packages/django/core/management/__init__.py", line 375, in execute
    self.fetch_command(subcommand).run_from_argv(self.argv)
  File "/home/vagrant/env/lib/python3.6/site-packages/django/core/management/base.py", line 323, in run_from_argv
    self.execute(*args, **cmd_options)
  File "/home/vagrant/env/lib/python3.6/site-packages/django/contrib/auth/management/commands/createsuperuser.py", line 61, in execute
    return super().execute(*args, **options)
  File "/home/vagrant/env/lib/python3.6/site-packages/django/core/management/base.py", line 364, in execute
    output = self.handle(*args, **options)
  File "/home/vagrant/env/lib/python3.6/site-packages/django/contrib/auth/management/commands/createsuperuser.py", line 156, in handle
    self.UserModel._default_manager.db_manager(database).create_superuser(**user_data)
TypeError: create_superuser() missing 1 required positional argument: 'name'
(env) vagrant@ubuntu-bionic:/vagrant$ python manage.py createsuperuser
Email: sanjaynithi0@gmail.com
Password:
Password (again):
This password is too short. It must contain at least 8 characters.
This password is too common.
This password is entirely numeric.
Bypass password validation and create user anyway? [y/N]: y
Traceback (most recent call last):
  File "manage.py", line 21, in <module>
    main()
  File "manage.py", line 17, in main
    execute_from_command_line(sys.argv)
  File "/home/vagrant/env/lib/python3.6/site-packages/django/core/management/__init__.py", line 381, in execute_from_command_line
    utility.execute()
  File "/home/vagrant/env/lib/python3.6/site-packages/django/core/management/__init__.py", line 375, in execute
    self.fetch_command(subcommand).run_from_argv(self.argv)
  File "/home/vagrant/env/lib/python3.6/site-packages/django/core/management/base.py", line 323, in run_from_argv
    self.execute(*args, **cmd_options)
  File "/home/vagrant/env/lib/python3.6/site-packages/django/contrib/auth/management/commands/createsuperuser.py", line 61, in execute
    return super().execute(*args, **options)
  File "/home/vagrant/env/lib/python3.6/site-packages/django/core/management/base.py", line 364, in execute
    output = self.handle(*args, **options)
  File "/home/vagrant/env/lib/python3.6/site-packages/django/contrib/auth/management/commands/createsuperuser.py", line 156, in handle
    self.UserModel._default_manager.db_manager(database).create_superuser(**user_data)
TypeError: create_superuser() missing 1 required positional argument: 'name'
(env) vagrant@ubuntu-bionic:/vagrant$ python manage.py createsuperuser
Email: sanjaynithi0@gmail.com
Password:
Password (again):
Error: Your passwords didn't match.
Password:
Password (again):
This password is too short. It must contain at least 8 characters.
This password is too common.
This password is entirely numeric.
Bypass password validation and create user anyway? [y/N]: y
Traceback (most recent call last):
  File "manage.py", line 21, in <module>
    main()
  File "manage.py", line 17, in main
    execute_from_command_line(sys.argv)
  File "/home/vagrant/env/lib/python3.6/site-packages/django/core/management/__init__.py", line 381, in execute_from_command_line
    utility.execute()
  File "/home/vagrant/env/lib/python3.6/site-packages/django/core/management/__init__.py", line 375, in execute
    self.fetch_command(subcommand).run_from_argv(self.argv)
  File "/home/vagrant/env/lib/python3.6/site-packages/django/core/management/base.py", line 323, in run_from_argv
    self.execute(*args, **cmd_options)
  File "/home/vagrant/env/lib/python3.6/site-packages/django/contrib/auth/management/commands/createsuperuser.py", line 61, in execute
    return super().execute(*args, **options)
  File "/home/vagrant/env/lib/python3.6/site-packages/django/core/management/base.py", line 364, in execute
    output = self.handle(*args, **options)
  File "/home/vagrant/env/lib/python3.6/site-packages/django/contrib/auth/management/commands/createsuperuser.py", line 156, in handle
    self.UserModel._default_manager.db_manager(database).create_superuser(**user_data)
TypeError: create_superuser() missing 1 required positional argument: 'name'
(env) vagrant@ubuntu-bionic:/vagrant$ python manage.py createsuperuser
Traceback (most recent call last):
  File "manage.py", line 21, in <module>
    main()
  File "manage.py", line 17, in main
    execute_from_command_line(sys.argv)
  File "/home/vagrant/env/lib/python3.6/site-packages/django/core/management/__init__.py", line 381, in execute_from_command_line
    utility.execute()
  File "/home/vagrant/env/lib/python3.6/site-packages/django/core/management/__init__.py", line 357, in execute
    django.setup()
  File "/home/vagrant/env/lib/python3.6/site-packages/django/__init__.py", line 24, in setup
    apps.populate(settings.INSTALLED_APPS)
  File "/home/vagrant/env/lib/python3.6/site-packages/django/apps/registry.py", line 114, in populate
    app_config.import_models()
  File "/home/vagrant/env/lib/python3.6/site-packages/django/apps/config.py", line 211, in import_models
    self.models_module = import_module(models_module_name)
  File "/usr/lib/python3.6/importlib/__init__.py", line 126, in import_module
    return _bootstrap._gcd_import(name[level:], package, level)
  File "<frozen importlib._bootstrap>", line 994, in _gcd_import
  File "<frozen importlib._bootstrap>", line 971, in _find_and_load
  File "<frozen importlib._bootstrap>", line 955, in _find_and_load_unlocked
  File "<frozen importlib._bootstrap>", line 665, in _load_unlocked
  File "<frozen importlib._bootstrap_external>", line 674, in exec_module
  File "<frozen importlib._bootstrap_external>", line 781, in get_code
  File "<frozen importlib._bootstrap_external>", line 741, in source_to_code
  File "<frozen importlib._bootstrap>", line 219, in _call_with_frames_removed
  File "/vagrant/profiles_api/models.py", line 11
    """Create a new user profile"""
                                  ^
TabError: inconsistent use of tabs and spaces in indentation
(env) vagrant@ubuntu-bionic:/vagrant$ python manage.py createsuperuser
Traceback (most recent call last):
  File "manage.py", line 21, in <module>
    main()
  File "manage.py", line 17, in main
    execute_from_command_line(sys.argv)
  File "/home/vagrant/env/lib/python3.6/site-packages/django/core/management/__init__.py", line 381, in execute_from_command_line
    utility.execute()
  File "/home/vagrant/env/lib/python3.6/site-packages/django/core/management/__init__.py", line 357, in execute
    django.setup()
  File "/home/vagrant/env/lib/python3.6/site-packages/django/__init__.py", line 24, in setup
    apps.populate(settings.INSTALLED_APPS)
  File "/home/vagrant/env/lib/python3.6/site-packages/django/apps/registry.py", line 114, in populate
    app_config.import_models()
  File "/home/vagrant/env/lib/python3.6/site-packages/django/apps/config.py", line 211, in import_models
    self.models_module = import_module(models_module_name)
  File "/usr/lib/python3.6/importlib/__init__.py", line 126, in import_module
    return _bootstrap._gcd_import(name[level:], package, level)
  File "<frozen importlib._bootstrap>", line 994, in _gcd_import
  File "<frozen importlib._bootstrap>", line 971, in _find_and_load
  File "<frozen importlib._bootstrap>", line 955, in _find_and_load_unlocked
  File "<frozen importlib._bootstrap>", line 665, in _load_unlocked
  File "<frozen importlib._bootstrap_external>", line 674, in exec_module
  File "<frozen importlib._bootstrap_external>", line 781, in get_code
  File "<frozen importlib._bootstrap_external>", line 741, in source_to_code
  File "<frozen importlib._bootstrap>", line 219, in _call_with_frames_removed
  File "/vagrant/profiles_api/models.py", line 11
    if not email:
                ^
TabError: inconsistent use of tabs and spaces in indentation
(env) vagrant@ubuntu-bionic:/vagrant$ python manage.py createsuperuser
Traceback (most recent call last):
  File "manage.py", line 21, in <module>
    main()
  File "manage.py", line 17, in main
    execute_from_command_line(sys.argv)
  File "/home/vagrant/env/lib/python3.6/site-packages/django/core/management/__init__.py", line 381, in execute_from_command_line
    utility.execute()
  File "/home/vagrant/env/lib/python3.6/site-packages/django/core/management/__init__.py", line 357, in execute
    django.setup()
  File "/home/vagrant/env/lib/python3.6/site-packages/django/__init__.py", line 24, in setup
    apps.populate(settings.INSTALLED_APPS)
  File "/home/vagrant/env/lib/python3.6/site-packages/django/apps/registry.py", line 114, in populate
    app_config.import_models()
  File "/home/vagrant/env/lib/python3.6/site-packages/django/apps/config.py", line 211, in import_models
    self.models_module = import_module(models_module_name)
  File "/usr/lib/python3.6/importlib/__init__.py", line 126, in import_module
    return _bootstrap._gcd_import(name[level:], package, level)
  File "<frozen importlib._bootstrap>", line 994, in _gcd_import
  File "<frozen importlib._bootstrap>", line 971, in _find_and_load
  File "<frozen importlib._bootstrap>", line 955, in _find_and_load_unlocked
  File "<frozen importlib._bootstrap>", line 665, in _load_unlocked
  File "<frozen importlib._bootstrap_external>", line 674, in exec_module
  File "<frozen importlib._bootstrap_external>", line 781, in get_code
  File "<frozen importlib._bootstrap_external>", line 741, in source_to_code
  File "<frozen importlib._bootstrap>", line 219, in _call_with_frames_removed
  File "/vagrant/profiles_api/models.py", line 11
    """Create a new user profile"""
                                  ^
TabError: inconsistent use of tabs and spaces in indentation
(env) vagrant@ubuntu-bionic:/vagrant$ python manage.py createsuperuser
Traceback (most recent call last):
  File "manage.py", line 21, in <module>
    main()
  File "manage.py", line 17, in main
    execute_from_command_line(sys.argv)
  File "/home/vagrant/env/lib/python3.6/site-packages/django/core/management/__init__.py", line 381, in execute_from_command_line
    utility.execute()
  File "/home/vagrant/env/lib/python3.6/site-packages/django/core/management/__init__.py", line 357, in execute
    django.setup()
  File "/home/vagrant/env/lib/python3.6/site-packages/django/__init__.py", line 24, in setup
    apps.populate(settings.INSTALLED_APPS)
  File "/home/vagrant/env/lib/python3.6/site-packages/django/apps/registry.py", line 114, in populate
    app_config.import_models()
  File "/home/vagrant/env/lib/python3.6/site-packages/django/apps/config.py", line 211, in import_models
    self.models_module = import_module(models_module_name)
  File "/usr/lib/python3.6/importlib/__init__.py", line 126, in import_module
    return _bootstrap._gcd_import(name[level:], package, level)
  File "<frozen importlib._bootstrap>", line 994, in _gcd_import
  File "<frozen importlib._bootstrap>", line 971, in _find_and_load
  File "<frozen importlib._bootstrap>", line 955, in _find_and_load_unlocked
  File "<frozen importlib._bootstrap>", line 665, in _load_unlocked
  File "<frozen importlib._bootstrap_external>", line 674, in exec_module
  File "<frozen importlib._bootstrap_external>", line 781, in get_code
  File "<frozen importlib._bootstrap_external>", line 741, in source_to_code
  File "<frozen importlib._bootstrap>", line 219, in _call_with_frames_removed
  File "/vagrant/profiles_api/models.py", line 10
    """Create a new user profile"""
                                  ^
TabError: inconsistent use of tabs and spaces in indentation
(env) vagrant@ubuntu-bionic:/vagrant$ python manage.py createsuperuser
Traceback (most recent call last):
  File "manage.py", line 21, in <module>
    main()
  File "manage.py", line 17, in main
    execute_from_command_line(sys.argv)
  File "/home/vagrant/env/lib/python3.6/site-packages/django/core/management/__init__.py", line 381, in execute_from_command_line
    utility.execute()
  File "/home/vagrant/env/lib/python3.6/site-packages/django/core/management/__init__.py", line 357, in execute
    django.setup()
  File "/home/vagrant/env/lib/python3.6/site-packages/django/__init__.py", line 24, in setup
    apps.populate(settings.INSTALLED_APPS)
  File "/home/vagrant/env/lib/python3.6/site-packages/django/apps/registry.py", line 114, in populate
    app_config.import_models()
  File "/home/vagrant/env/lib/python3.6/site-packages/django/apps/config.py", line 211, in import_models
    self.models_module = import_module(models_module_name)
  File "/usr/lib/python3.6/importlib/__init__.py", line 126, in import_module
    return _bootstrap._gcd_import(name[level:], package, level)
  File "<frozen importlib._bootstrap>", line 994, in _gcd_import
  File "<frozen importlib._bootstrap>", line 971, in _find_and_load
  File "<frozen importlib._bootstrap>", line 955, in _find_and_load_unlocked
  File "<frozen importlib._bootstrap>", line 665, in _load_unlocked
  File "<frozen importlib._bootstrap_external>", line 674, in exec_module
  File "<frozen importlib._bootstrap_external>", line 781, in get_code
  File "<frozen importlib._bootstrap_external>", line 741, in source_to_code
  File "<frozen importlib._bootstrap>", line 219, in _call_with_frames_removed
  File "/vagrant/profiles_api/models.py", line 11
    def create_user(self,email,name,password=None):
    ^
IndentationError: unexpected indent
(env) vagrant@ubuntu-bionic:/vagrant$ python manage.py createsuperuser
Email: sanjaynithi0@gmail.com
Name: Sanjay
Password:
Password (again):
This password is too short. It must contain at least 8 characters.
This password is too common.
This password is entirely numeric.
Bypass password validation and create user anyway? [y/N]: y
Superuser created successfully.
(env) vagrant@ubuntu-bionic:/vagrant$ python manage.py createsuperuser
Email: sa
Error: Enter a valid email address.
Email: sanjatadhitya2000@gmail.com
Name: sanjayadhi
Password:
Password (again):
This password is too short. It must contain at least 8 characters.
This password is too common.
This password is entirely numeric.
Bypass password validation and create user anyway? [y/N]: y
Superuser created successfully.
(env) vagrant@ubuntu-bionic:/vagrant$
